Workbook

Sheet Cognos_Office_Connection_Cache

Sheet PL
C1: KOÇTAŞ YAPI MARKETLERİ TİCARET ANONİM ŞİRKETİ | D1: Masraf Merkezi | E1: {=_xll.SUBNM("tm1:Masraf_Kar_Merkezleri","All Roots",1,"Code - Name")} -> Koçtaş Total | F1: Dönem Seçiniz: | G1: {=_xll.SUBNM("tm1:Period","2024 - 2025",12,"")} -> 2024-11
C2: PROFIT & LOSS STATEMENT
C3: (Koçtaş Total )
A5: tm1:PL Fiili | D5: Dönem | E5: =G1 -> 2024-11 | F5: Dönem | H5: =G1 -> 2024-11 | J5: Dönem | L5: =G1 -> 2024-11 | N5: Dönem | O5: {=_xll.DBRA(A12,$E$5,"PYMonth")} -> 2023-11 | Q5: Dönem | R5: =E5 -> 2024-11 | S5: Dönem | U5: =H5 -> 2024-11 | W5: Dönem | Y5: =L5 -> 2024-11 | AA5: Dönem | AB5: =O5 -> 2023-11
A6: tm1:PL | D6: Fiili Senaryo Seçiniz: | E6: {=_xll.DBR($A$8,"IFRS Senaryo","Değer")} -> Fiili | F6: Bütçe Versiyonu Seçiniz: | H6: {=_xll.SUBNM("tm1:Version","Tüm Versiyonlar",2,"")} -> Budget 2024 | Arşiv | J6: Forecast Versiyonu Seçiniz: | L6: {=_xll.SUBNM("tm1:Version","Tüm Versiyonlar",5,"")} -> Forecast 9+3 2024 | Arşiv | N6: Fiili Senaryo Seçiniz: | O6: =E6 -> Fiili | Q6: Fiili Senaryo Seçiniz: | R6: =E6 -> Fiili | S6: Bütçe Versiyonu Seçiniz: | U6: =H6 -> Budget 2024 | Arşiv | W6: Forecast Versiyonu Seçiniz: | Y6: =L6 -> Forecast 9+3 2024 | Arşiv | AA6: Fiili Senaryo Seçiniz: | AB6: =E6 -> Fiili
A8: tm1:Sistem | D8: MONTHLY | F8: MONTHLY | J8: MONTHLY | N8: MONTHLY | Q8: YTD | S8: YTD | W8: YTD | AA8: YTD
D9: Actual | E9: Sales % | F9: =H6 -> Budget 2024 | Arşiv | G9: Var. Actual | H9: Sales % | I9: Actual vs Budget | J9: =L6 -> Forecast 9+3 2024 | Arşiv | K9: Var. Actual | L9: Sales % | M9: Actual vs Forecast | N9: LY | O9: Sales % | Q9: Actual | R9: Sales % | S9: =U6 -> Budget 2024 | Arşiv | T9: Var. Actual | U9: Sales % | V9: Actual vs Budget | W9: =Y6 -> Forecast 9+3 2024 | Arşiv | X9: Var. Actual | Y9: Sales % | Z9: Actual vs Forecast | AA9: LY | AB9: Sales %
C10: GROSS SALES | D10: =IFERROR(D12-D11,0) -> 0 | F10: =IFERROR(F12-F11,0) -> 1.6466209e+09 | G10: =IFERROR(D10-F10,0) -> -1.6466209e+09 | I10: =IFERROR((D10-F10)/ABS(F10),0) -> -1 | J10: =IFERROR(J12-J11,0) -> 1.0351993e+09 | K10: =IFERROR(D10-J10,0) -> -1.0351993e+09 | M10: =IFERROR((D10-J10)/ABS(J10),0) -> -1 | N10: =IFERROR(N12-N11,0) -> 9.2802373e+08 | Q10: =IFERROR(Q12-Q11,0) -> 1.1514981e+10 | S10: =IFERROR(S12-S11,0) -> 1.5440631e+10 | T10: =IFERROR(Q10-S10,0) -> -3.9256505e+09 | V10: =IFERROR((Q10-S10)/ABS(S10),0) -> -0.25424157 | W10: =IFERROR(W12-W11,0) -> 1.2572972e+10 | X10: =IFERROR(Q10-W10,0) -> -1.0579906e+09 | Z10: =IFERROR((Q10-W10)/ABS(W10),0) -> -0.084148012 | AA10: =IFERROR(AA12-AA11,0) -> 9.4808935e+09
C11: Product discounts given | D11: {=_xll.DBR($A$5,C11,$E$1,$E$6,$E$5,"Amount")} -> 0 | E11: =IFERROR(D11/$D$12,0) -> 0 | F11: {=_xll.DBR($A$6,C11,"Total Source",$E$1,$H$6,$H$5,"Amount")} -> -50049525 | G11: =IFERROR(D11-F11,0) -> 50049525 | H11: =IFERROR(F11/$F$12,0) -> -0.031348128 | I11: =IFERROR((D11-F11)/ABS(F11),0) -> 1 | J11: {=_xll.DBR($A$6,C11,"Total Source",$E$1,$L$6,$L$5,"Amount")} -> -30705061 | K11: =IFERROR(D11-J11,0) -> 30705061 | L11: =IFERROR(J11/$J$12,0) -> -0.030567682 | M11: =IFERROR((D11-J11)/ABS(J11),0) -> 1 | N11: {=_xll.DBR($A$5,C11,$E$1,$O$6,$O$5,"Amount")} -> -26332139 | O11: =IFERROR(N11/$N$12,0) -> -0.029203043 | Q11: {=_xll.DBR($A$5,C11,$E$1,$R$6,$R$5&"-YTD","Amount")} -> -3.7971088e+08 | R11: =IFERROR(Q11/$Q$12,0) -> -0.034099835 | S11: {=_xll.DBR($A$6,C11,"Total Source",$E$1,$U$6,$U$5&"-YTD","Amount")} -> -4.7649276e+08 | T11: =IFERROR(Q11-S11,0) -> 96781880 | U11: =IFERROR(S11/$S$12,0) -> -0.031842311 | V11: =IFERROR((Q11-S11)/ABS(S11),0) -> 0.20311301 | W11: {=_xll.DBR($A$6,C11,"Total Source",$E$1,$Y$6,$Y$5&"-YTD","Amount")} -> -4.1145609e+08 | X11: =IFERROR(Q11-W11,0) -> 31745212 | Y11: =IFERROR(W11/$W$12,0) -> -0.033832633 | Z11: =IFERROR((Q11-W11)/ABS(W11),0) -> 0.077153341 | AA11: {=_xll.DBR($A$5,C11,$E$1,$AB$6,$AB$5&"-YTD","Amount")} -> -3.0999378e+08 | AB11: =IFERROR(AA11/$AA$12,0) -> -0.033801894
A12: tm1:Period | C12: NET SALES | D12: {=_xll.DBR($A$5,C12,$E$1,$E$6,$E$5,"Amount")} -> 0 | E12: =IFERROR(D12/$D$12,0) -> 0 | F12: {=_xll.DBR($A$6,C12,"Total Source",$E$1,$H$6,$H$5,"Amount")} -> 1.5965714e+09 | G12: =IFERROR(D12-F12,0) -> -1.5965714e+09 | H12: =IFERROR(F12/$F$12,0) -> 1 | I12: =IFERROR((D12-F12)/ABS(F12),0) -> -1 | J12: {=_xll.DBR($A$6,C12,"Total Source",$E$1,$L$6,$L$5,"Amount")} -> 1.0044943e+09 | K12: =IFERROR(D12-J12,0) -> -1.0044943e+09 | L12: =IFERROR(J12/$J$12,0) -> 1 | M12: =IFERROR((D12-J12)/ABS(J12),0) -> -1 | N12: {=_xll.DBR($A$5,C12,$E$1,$O$6,$O$5,"Amount")} -> 9.0169159e+08 | O12: =IFERROR(N12/$N$12,0) -> 1 | Q12: {=_xll.DBR($A$5,C12,$E$1,$R$6,$R$5&"-YTD","Amount")} -> 1.113527e+10 | R12: =IFERROR(Q12/$Q$12,0) -> 1 | S12: {=_xll.DBR($A$6,C12,"Total Source",$E$1,$U$6,$U$5&"-YTD","Amount")} -> 1.4964139e+10 | T12: =IFERROR(Q12-S12,0) -> -3.8288686e+09 | U12: =IFERROR(S12/$S$12,0) -> 1 | V12: =IFERROR((Q12-S12)/ABS(S12),0) -> -0.25586963 | W12: {=_xll.DBR($A$6,C12,"Total Source",$E$1,$Y$6,$Y$5&"-YTD","Amount")} -> 1.2161516e+10 | X12: =IFERROR(Q12-W12,0) -> -1.0262454e+09 | Y12: =IFERROR(W12/$W$12,0) -> 1 | Z12: =IFERROR((Q12-W12)/ABS(W12),0) -> -0.08438466 | AA12: {=_xll.DBR($A$5,C12,$E$1,$AB$6,$AB$5&"-YTD","Amount")} -> 9.1708997e+09 | AB12: =IFERROR(AA12/$AA$12,0) -> 1
C13: Buying margin | D13: {=_xll.DBR($A$5,C13,$E$1,$E$6,$E$5,"Amount")+_xll.DBR($A$5,C11,$E$1,$E$6,$E$5,"Amount")} -> -2.5477213e+08 | E13: =IFERROR(D13/$D$12,0) -> 0 | F13: {=_xll.DBR($A$6,C13,"Total Source",$E$1,$H$6,$H$5,"Amount")+_xll.DBR($A$6,C11,"Total Source",$E$1,$H$6,$H$5,"Amount")} -> 4.827109e+08 | J13: {=_xll.DBR($A$6,C13,"Total Source",$E$1,$L$6,$L$5,"Amount")+_xll.DBR($A$6,C11,"Total Source",$E$1,$L$6,$L$5,"Amount")} -> 3.4640501e+08 | N13: {=_xll.DBR($A$5,C13,$E$1,$O$6,$O$5,"Amount")+_xll.DBR($A$5,C11,$E$1,$O$6,$O$5,"Amount")} -> 2.4229364e+08 | Q13: {=_xll.DBR($A$5,C13,$E$1,$R$6,$R$5&"-YTD","Amount")+-184074487.41} -> 3.5521184e+09 | S13: {=_xll.DBR($A$6,C13,"Total Source",$E$1,$U$6,$U$5&"-YTD","Amount")+_xll.DBR($A$6,C11,"Total Source",$E$1,$U$6,$U$5&"-YTD","Amount")} -> 4.5900703e+09 | W13: {=_xll.DBR($A$6,C13,"Total Source",$E$1,$Y$6,$Y$5&"-YTD","Amount")+_xll.DBR($A$6,C11,"Total Source",$E$1,$Y$6,$Y$5&"-YTD","Amount")} -> 3.9723409e+09 | AA13: {=_xll.DBR($A$5,C13,$E$1,$AB$6,$AB$5&"-YTD","Amount")+_xll.DBR($A$5,C11,$E$1,$AB$6,$AB$5&"-YTD","Amount")} -> 2.6762749e+09
C14: Stock transfer cost | D14: {=_xll.DBR($A$5,C14,$E$1,$E$6,$E$5,"Amount")} -> 0 | E14: =IFERROR(D14/$D$12,0) -> 0 | F14: {=_xll.DBR($A$6,C14,"Total Source",$E$1,$H$6,$H$5,"Amount")} -> -13725130 | G14: =IFERROR(D14-F14,0) -> 13725130 | H14: =IFERROR(F14/$F$12,0) -> -0.0085966277 | I14: =IFERROR((D14-F14)/ABS(F14),0) -> 1 | J14: {=_xll.DBR($A$6,C14,"Total Source",$E$1,$L$6,$L$5,"Amount")} -> -11492280 | K14: =IFERROR(D14-J14,0) -> 11492280 | L14: =IFERROR(J14/$J$12,0) -> -0.011440862 | M14: =IFERROR((D14-J14)/ABS(J14),0) -> 1 | N14: {=_xll.DBR($A$5,C14,$E$1,$O$6,$O$5,"Amount")} -> -9055086.5 | O14: =IFERROR(N14/$N$12,0) -> -0.010042332 | Q14: {=_xll.DBR($A$5,C14,$E$1,$R$6,$R$5&"-YTD","Amount")} -> -1.0524116e+08 | R14: =IFERROR(Q14/$Q$12,0) -> -0.0094511547 | S14: {=_xll.DBR($A$6,C14,"Total Source",$E$1,$U$6,$U$5&"-YTD","Amount")} -> -141770928 | T14: =IFERROR(Q14-S14,0) -> 36529767 | U14: =IFERROR(S14/$S$12,0) -> -0.0094740453 | V14: =IFERROR((Q14-S14)/ABS(S14),0) -> 0.25766754 | W14: {=_xll.DBR($A$6,C14,"Total Source",$E$1,$Y$6,$Y$5&"-YTD","Amount")} -> -1.1828849e+08 | X14: =IFERROR(Q14-W14,0) -> 13047331 | Y14: =IFERROR(W14/$W$12,0) -> -0.0097264599 | Z14: =IFERROR((Q14-W14)/ABS(W14),0) -> 0.11030093 | AA14: {=_xll.DBR($A$5,C14,$E$1,$AB$6,$AB$5&"-YTD","Amount")} -> -90820305 | AB14: =IFERROR(AA14/$AA$12,0) -> -0.0099030966
C15: Supplier rebates | D15: {=_xll.DBR($A$5,C15,$E$1,$E$6,$E$5,"Amount")} -> -6277547.6 | E15: =IFERROR(D15/$D$12,0) -> 0 | F15: {=_xll.DBR($A$6,C15,"Total Source",$E$1,$H$6,$H$5,"Amount")} -> 1.1919072e+08 | G15: =IFERROR(D15-F15,0) -> -1.2546827e+08 | H15: =IFERROR(F15/$F$12,0) -> 0.074654174 | I15: =IFERROR((D15-F15)/ABS(F15),0) -> -1.0526681 | J15: {=_xll.DBR($A$6,C15,"Total Source",$E$1,$L$6,$L$5,"Amount")} -> 74472384 | K15: =IFERROR(D15-J15,0) -> -80749931 | L15: =IFERROR(J15/$J$12,0) -> 0.074139183 | M15: =IFERROR((D15-J15)/ABS(J15),0) -> -1.0842936 | N15: {=_xll.DBR($A$5,C15,$E$1,$O$6,$O$5,"Amount")} -> 83789434 | O15: =IFERROR(N15/$N$12,0) -> 0.092924715 | Q15: {=_xll.DBR($A$5,C15,$E$1,$R$6,$R$5&"-YTD","Amount")} -> 6.9107884e+08 | R15: =IFERROR(Q15/$Q$12,0) -> 0.062062153 | S15: {=_xll.DBR($A$6,C15,"Total Source",$E$1,$U$6,$U$5&"-YTD","Amount")} -> 1.0762751e+09 | T15: =IFERROR(Q15-S15,0) -> -3.8519623e+08 | U15: =IFERROR(S15/$S$12,0) -> 0.071923622 | V15: =IFERROR((Q15-S15)/ABS(S15),0) -> -0.35789757 | W15: {=_xll.DBR($A$6,C15,"Total Source",$E$1,$Y$6,$Y$5&"-YTD","Amount")} -> 7.8242633e+08 | X15: =IFERROR(Q15-W15,0) -> -91347496 | Y15: =IFERROR(W15/$W$12,0) -> 0.064336253 | Z15: =IFERROR((Q15-W15)/ABS(W15),0) -> -0.11674901 | AA15: {=_xll.DBR($A$5,C15,$E$1,$AB$6,$AB$5&"-YTD","Amount")} -> 8.1659124e+08 | AB15: =IFERROR(AA15/$AA$12,0) -> 0.089041563
C16: Delivery | D16: {=_xll.DBR($A$5,C16,$E$1,$E$6,$E$5,"Amount")} -> 0 | E16: =IFERROR(D16/$D$12,0) -> 0 | F16: {=_xll.DBR($A$6,C16,"Total Source",$E$1,$H$6,$H$5,"Amount")} -> -21759139 | G16: =IFERROR(D16-F16,0) -> 21759139 | H16: =IFERROR(F16/$F$12,0) -> -0.013628666 | I16: =IFERROR((D16-F16)/ABS(F16),0) -> 1 | J16: {=_xll.DBR($A$6,C16,"Total Source",$E$1,$L$6,$L$5,"Amount")} -> -13990168 | K16: =IFERROR(D16-J16,0) -> 13990168 | L16: =IFERROR(J16/$J$12,0) -> -0.013927574 | M16: =IFERROR((D16-J16)/ABS(J16),0) -> 1 | N16: {=_xll.DBR($A$5,C16,$E$1,$O$6,$O$5,"Amount")} -> -6518451.3 | O16: =IFERROR(N16/$N$12,0) -> -0.0072291362 | Q16: {=_xll.DBR($A$5,C16,$E$1,$R$6,$R$5&"-YTD","Amount")} -> -1.3324791e+08 | R16: =IFERROR(Q16/$Q$12,0) -> -0.011966293 | S16: {=_xll.DBR($A$6,C16,"Total Source",$E$1,$U$6,$U$5&"-YTD","Amount")} -> -1.8137799e+08 | T16: =IFERROR(Q16-S16,0) -> 48130077 | U16: =IFERROR(S16/$S$12,0) -> -0.012120844 | V16: =IFERROR((Q16-S16)/ABS(S16),0) -> 0.26535787 | W16: {=_xll.DBR($A$6,C16,"Total Source",$E$1,$Y$6,$Y$5&"-YTD","Amount")} -> -1.5127289e+08 | X16: =IFERROR(Q16-W16,0) -> 18024984 | Y16: =IFERROR(W16/$W$12,0) -> -0.012438655 | Z16: =IFERROR((Q16-W16)/ABS(W16),0) -> 0.11915541 | AA16: {=_xll.DBR($A$5,C16,$E$1,$AB$6,$AB$5&"-YTD","Amount")} -> -1.2728949e+08 | AB16: =IFERROR(AA16/$AA$12,0) -> -0.013879717
C17: Shrinkage | D17: {=_xll.DBR($A$5,C17,$E$1,$E$6,$E$5,"Amount")} -> 1841152.1 | E17: =IFERROR(D17/$D$12,0) -> 0 | F17: {=_xll.DBR($A$6,C17,"Total Source",$E$1,$H$6,$H$5,"Amount")} -> -4947807.9 | G17: =IFERROR(D17-F17,0) -> 6788960 | H17: =IFERROR(F17/$F$12,0) -> -0.0030990207 | I17: =IFERROR((D17-F17)/ABS(F17),0) -> 1.3721147 | J17: {=_xll.DBR($A$6,C17,"Total Source",$E$1,$L$6,$L$5,"Amount")} -> -6887146.7 | K17: =IFERROR(D17-J17,0) -> 8728298.8 | L17: =IFERROR(J17/$J$12,0) -> -0.0068563326 | M17: =IFERROR((D17-J17)/ABS(J17),0) -> 1.2673316 | N17: {=_xll.DBR($A$5,C17,$E$1,$O$6,$O$5,"Amount")} -> -4443813.1 | O17: =IFERROR(N17/$N$12,0) -> -0.0049283072 | Q17: {=_xll.DBR($A$5,C17,$E$1,$R$6,$R$5&"-YTD","Amount")} -> -53349457 | R17: =IFERROR(Q17/$Q$12,0) -> -0.0047910339 | S17: {=_xll.DBR($A$6,C17,"Total Source",$E$1,$U$6,$U$5&"-YTD","Amount")} -> -61138177 | T17: =IFERROR(Q17-S17,0) -> 7788719.8 | U17: =IFERROR(S17/$S$12,0) -> -0.0040856462 | V17: =IFERROR((Q17-S17)/ABS(S17),0) -> 0.12739536 | W17: {=_xll.DBR($A$6,C17,"Total Source",$E$1,$Y$6,$Y$5&"-YTD","Amount")} -> -59434174 | X17: =IFERROR(Q17-W17,0) -> 6084717.1 | Y17: =IFERROR(W17/$W$12,0) -> -0.0048870697 | Z17: =IFERROR((Q17-W17)/ABS(W17),0) -> 0.10237742 | AA17: {=_xll.DBR($A$5,C17,$E$1,$AB$6,$AB$5&"-YTD","Amount")} -> -37378078 | AB17: =IFERROR(AA17/$AA$12,0) -> -0.0040757263
C18: Distribution costs | D18: {=_xll.DBR($A$5,C18,$E$1,$E$6,$E$5,"Amount")} -> -14424652 | E18: =IFERROR(D18/$D$12,0) -> 0 | F18: {=_xll.DBR($A$6,C18,"Total Source",$E$1,$H$6,$H$5,"Amount")} -> -24158506 | G18: =IFERROR(D18-F18,0) -> 9733853.7 | H18: =IFERROR(F18/$F$12,0) -> -0.015131491 | I18: =IFERROR((D18-F18)/ABS(F18),0) -> 0.40291621 | J18: {=_xll.DBR($A$6,C18,"Total Source",$E$1,$L$6,$L$5,"Amount")} -> -21560051 | K18: =IFERROR(D18-J18,0) -> 7135398.7 | L18: =IFERROR(J18/$J$12,0) -> -0.021463588 | M18: =IFERROR((D18-J18)/ABS(J18),0) -> 0.33095463 | N18: {=_xll.DBR($A$5,C18,$E$1,$O$6,$O$5,"Amount")} -> -19895339 | O18: =IFERROR(N18/$N$12,0) -> -0.022064461 | Q18: {=_xll.DBR($A$5,C18,$E$1,$R$6,$R$5&"-YTD","Amount")} -> -2.1869782e+08 | R18: =IFERROR(Q18/$Q$12,0) -> -0.0196401 | S18: {=_xll.DBR($A$6,C18,"Total Source",$E$1,$U$6,$U$5&"-YTD","Amount")} -> -2.3951659e+08 | T18: =IFERROR(Q18-S18,0) -> 20818775 | U18: =IFERROR(S18/$S$12,0) -> -0.016006039 | V18: =IFERROR((Q18-S18)/ABS(S18),0) -> 0.086919968 | W18: {=_xll.DBR($A$6,C18,"Total Source",$E$1,$Y$6,$Y$5&"-YTD","Amount")} -> -2.2885504e+08 | X18: =IFERROR(Q18-W18,0) -> 10157218 | Y18: =IFERROR(W18/$W$12,0) -> -0.01881797 | Z18: =IFERROR((Q18-W18)/ABS(W18),0) -> 0.04438276 | AA18: {=_xll.DBR($A$5,C18,$E$1,$AB$6,$AB$5&"-YTD","Amount")} -> -1.6326445e+08 | AB18: =IFERROR(AA18/$AA$12,0) -> -0.017802447
C19: Other margin
C20: Net margin | D20: {=_xll.DBR($A$5,C20,$E$1,$E$6,$E$5,"Amount")} -> -2.7363318e+08 | E20: =IFERROR(D20/$D$12,0) -> 0 | F20: {=_xll.DBR($A$6,C20,"Total Source",$E$1,$H$6,$H$5,"Amount")} -> 5.5427017e+08 | G20: =IFERROR(D20-F20,0) -> -8.2790335e+08 | H20: =IFERROR(F20/$F$12,0) -> 0.34716278 | I20: =IFERROR((D20-F20)/ABS(F20),0) -> -1.493682 | J20: {=_xll.DBR($A$6,C20,"Total Source",$E$1,$L$6,$L$5,"Amount")} -> 3.8977007e+08 | K20: =IFERROR(D20-J20,0) -> -6.6340325e+08 | L20: =IFERROR(J20/$J$12,0) -> 0.38802618 | M20: =IFERROR((D20-J20)/ABS(J20),0) -> -1.7020374 | N20: {=_xll.DBR($A$5,C20,$E$1,$O$6,$O$5,"Amount")} -> 2.9695565e+08 | O20: =IFERROR(N20/$N$12,0) -> 0.32933173 | Q20: {=_xll.DBR($A$5,C20,$E$1,$R$6,$R$5&"-YTD","Amount")} -> 3.7475364e+09 | R20: =IFERROR(Q20/$Q$12,0) -> 0.33654651 | S20: {=_xll.DBR($A$6,C20,"Total Source",$E$1,$U$6,$U$5&"-YTD","Amount")} -> 5.2012687e+09 | T20: =IFERROR(Q20-S20,0) -> -1.4537323e+09 | U20: =IFERROR(S20/$S$12,0) -> 0.34758223 | V20: =IFERROR((Q20-S20)/ABS(S20),0) -> -0.27949572 | W20: {=_xll.DBR($A$6,C20,"Total Source",$E$1,$Y$6,$Y$5&"-YTD","Amount")} -> 4.4270145e+09 | X20: =IFERROR(Q20-W20,0) -> -6.794781e+08 | Y20: =IFERROR(W20/$W$12,0) -> 0.36401832 | Z20: =IFERROR((Q20-W20)/ABS(W20),0) -> -0.1534845 | AA20: {=_xll.DBR($A$5,C20,$E$1,$AB$6,$AB$5&"-YTD","Amount")} -> 3.1135817e+09 | AB20: =IFERROR(AA20/$AA$12,0) -> 0.33950668
C21: Store costs | D21: {=_xll.DBR($A$5,C21,$E$1,$E$6,$E$5,"Amount")} -> -1.8073102e+08 | E21: =IFERROR(D21/$D$12,0) -> 0 | F21: {=_xll.DBR($A$6,C21,"Total Source",$E$1,$H$6,$H$5,"Amount")} -> -3.2722313e+08 | G21: =IFERROR(D21-F21,0) -> 1.4649212e+08 | H21: =IFERROR(F21/$F$12,0) -> -0.20495365 | I21: =IFERROR((D21-F21)/ABS(F21),0) -> 0.44768264 | J21: {=_xll.DBR($A$6,C21,"Total Source",$E$1,$L$6,$L$5,"Amount")} -> -3.320167e+08 | K21: =IFERROR(D21-J21,0) -> 1.5128569e+08 | L21: =IFERROR(J21/$J$12,0) -> -0.33053121 | M21: =IFERROR((D21-J21)/ABS(J21),0) -> 0.45565685 | N21: {=_xll.DBR($A$5,C21,$E$1,$O$6,$O$5,"Amount")} -> -2.4962488e+08 | O21: =IFERROR(N21/$N$12,0) -> -0.27684065 | Q21: {=_xll.DBR($A$5,C21,$E$1,$R$6,$R$5&"-YTD","Amount")} -> -3.8388545e+09 | R21: =IFERROR(Q21/$Q$12,0) -> -0.34474732 | S21: {=_xll.DBR($A$6,C21,"Total Source",$E$1,$U$6,$U$5&"-YTD","Amount")} -> -3.6863399e+09 | T21: =IFERROR(Q21-S21,0) -> -1.5251467e+08 | U21: =IFERROR(S21/$S$12,0) -> -0.24634494 | V21: =IFERROR((Q21-S21)/ABS(S21),0) -> -0.041372928 | W21: {=_xll.DBR($A$6,C21,"Total Source",$E$1,$Y$6,$Y$5&"-YTD","Amount")} -> -3.9348045e+09 | X21: =IFERROR(Q21-W21,0) -> 95949990 | Y21: =IFERROR(W21/$W$12,0) -> -0.32354558 | Z21: =IFERROR((Q21-W21)/ABS(W21),0) -> 0.024384944 | AA21: {=_xll.DBR($A$5,C21,$E$1,$AB$6,$AB$5&"-YTD","Amount")} -> -2.3007811e+09 | AB21: =IFERROR(AA21/$AA$12,0) -> -0.25087845
C22: - staff (Payroll) | D22: {=_xll.DBR($A$5,C22,$E$1,$E$6,$E$5,"Amount")} -> -3.9982711e-05 | E22: =IFERROR(D22/$D$12,0) -> 0 | F22: {=_xll.DBR($A$6,C22,"Total Source",$E$1,$H$6,$H$5,"Amount")} -> -1.3723632e+08 | G22: =IFERROR(D22-F22,0) -> 1.3723632e+08 | H22: =IFERROR(F22/$F$12,0) -> -0.085956892 | I22: =IFERROR((D22-F22)/ABS(F22),0) -> 1 | J22: {=_xll.DBR($A$6,C22,"Total Source",$E$1,$L$6,$L$5,"Amount")} -> -96247054 | K22: =IFERROR(D22-J22,0) -> 96247054 | L22: =IFERROR(J22/$J$12,0) -> -0.095816431 | M22: =IFERROR((D22-J22)/ABS(J22),0) -> 1 | N22: {=_xll.DBR($A$5,C22,$E$1,$O$6,$O$5,"Amount")} -> -93701133 | O22: =IFERROR(N22/$N$12,0) -> -0.10391705 | Q22: {=_xll.DBR($A$5,C22,$E$1,$R$6,$R$5&"-YTD","Amount")} -> -1.2219434e+09 | R22: =IFERROR(Q22/$Q$12,0) -> -0.1097363 | S22: {=_xll.DBR($A$6,C22,"Total Source",$E$1,$U$6,$U$5&"-YTD","Amount")} -> -1.4446804e+09 | T22: =IFERROR(Q22-S22,0) -> 2.22737e+08 | U22: =IFERROR(S22/$S$12,0) -> -0.096542834 | V22: =IFERROR((Q22-S22)/ABS(S22),0) -> 0.15417735 | W22: {=_xll.DBR($A$6,C22,"Total Source",$E$1,$Y$6,$Y$5&"-YTD","Amount")} -> -1.2983784e+09 | X22: =IFERROR(Q22-W22,0) -> 76435063 | Y22: =IFERROR(W22/$W$12,0) -> -0.10676124 | Z22: =IFERROR((Q22-W22)/ABS(W22),0) -> 0.058869634 | AA22: {=_xll.DBR($A$5,C22,$E$1,$AB$6,$AB$5&"-YTD","Amount")} -> -8.4242793e+08 | AB22: =IFERROR(AA22/$AA$12,0) -> -0.09185881
C23: - staff (exc. Payroll) | D23: {=_xll.DBR($A$5,C23,$E$1,$E$6,$E$5,"Amount")} -> 0 | E23: =IFERROR(D23/$D$12,0) -> 0 | F23: {=_xll.DBR($A$6,C23,"Total Source",$E$1,$H$6,$H$5,"Amount")} -> -32560312 | G23: =IFERROR(D23-F23,0) -> 32560312 | H23: =IFERROR(F23/$F$12,0) -> -0.020393897 | I23: =IFERROR((D23-F23)/ABS(F23),0) -> 1 | J23: {=_xll.DBR($A$6,C23,"Total Source",$E$1,$L$6,$L$5,"Amount")} -> -31821140 | K23: =IFERROR(D23-J23,0) -> 31821140 | L23: =IFERROR(J23/$J$12,0) -> -0.031678768 | M23: =IFERROR((D23-J23)/ABS(J23),0) -> 1 | N23: {=_xll.DBR($A$5,C23,$E$1,$O$6,$O$5,"Amount")} -> -24971371 | O23: =IFERROR(N23/$N$12,0) -> -0.027693916 | Q23: {=_xll.DBR($A$5,C23,$E$1,$R$6,$R$5&"-YTD","Amount")} -> -5.0713614e+08 | R23: =IFERROR(Q23/$Q$12,0) -> -0.045543228 | S23: {=_xll.DBR($A$6,C23,"Total Source",$E$1,$U$6,$U$5&"-YTD","Amount")} -> -4.2000913e+08 | T23: =IFERROR(Q23-S23,0) -> -87127016 | U23: =IFERROR(S23/$S$12,0) -> -0.028067711 | V23: =IFERROR((Q23-S23)/ABS(S23),0) -> -0.20744077 | W23: {=_xll.DBR($A$6,C23,"Total Source",$E$1,$Y$6,$Y$5&"-YTD","Amount")} -> -4.9357437e+08 | X23: =IFERROR(Q23-W23,0) -> -13561774 | Y23: =IFERROR(W23/$W$12,0) -> -0.040584939 | Z23: =IFERROR((Q23-W23)/ABS(W23),0) -> -0.027476658 | AA23: {=_xll.DBR($A$5,C23,$E$1,$AB$6,$AB$5&"-YTD","Amount")} -> -2.5938741e+08 | AB23: =IFERROR(AA23/$AA$12,0) -> -0.028283747
C24: - term. benefit provision | D24: {=_xll.DBR($A$5,C24,$E$1,$E$6,$E$5,"Amount")} -> -5033564.9 | E24: =IFERROR(D24/$D$12,0) -> 0 | F24: {=_xll.DBR($A$6,C24,"Total Source",$E$1,$H$6,$H$5,"Amount")} -> -1486212 | G24: =IFERROR(D24-F24,0) -> -3547352.9 | H24: =IFERROR(F24/$F$12,0) -> -0.00093087725 | I24: =IFERROR((D24-F24)/ABS(F24),0) -> -2.3868418 | J24: {=_xll.DBR($A$6,C24,"Total Source",$E$1,$L$6,$L$5,"Amount")} -> 1333668.1 | K24: =IFERROR(D24-J24,0) -> -6367232.9 | L24: =IFERROR(J24/$J$12,0) -> 0.001327701 | M24: =IFERROR((D24-J24)/ABS(J24),0) -> -4.7742262 | N24: {=_xll.DBR($A$5,C24,$E$1,$O$6,$O$5,"Amount")} -> -1030118.6 | O24: =IFERROR(N24/$N$12,0) -> -0.0011424289 | Q24: {=_xll.DBR($A$5,C24,$E$1,$R$6,$R$5&"-YTD","Amount")} -> -641401.13 | R24: =IFERROR(Q24/$Q$12,0) -> -5.7600859e-05 | S24: {=_xll.DBR($A$6,C24,"Total Source",$E$1,$U$6,$U$5&"-YTD","Amount")} -> -54928447 | T24: =IFERROR(Q24-S24,0) -> 54287046 | U24: =IFERROR(S24/$S$12,0) -> -0.0036706721 | V24: =IFERROR((Q24-S24)/ABS(S24),0) -> 0.98832297 | W24: {=_xll.DBR($A$6,C24,"Total Source",$E$1,$Y$6,$Y$5&"-YTD","Amount")} -> 4720742.9 | X24: =IFERROR(Q24-W24,0) -> -5362144.1 | Y24: =IFERROR(W24/$W$12,0) -> 0.00038817061 | Z24: =IFERROR((Q24-W24)/ABS(W24),0) -> -1.1358687 | AA24: {=_xll.DBR($A$5,C24,$E$1,$AB$6,$AB$5&"-YTD","Amount")} -> -3023079.7 | AB24: =IFERROR(AA24/$AA$12,0) -> -0.00032963829
C25: - bonus | D25: {=_xll.DBR($A$5,C25,$E$1,$E$6,$E$5,"Amount")} -> 0 | E25: =IFERROR(D25/$D$12,0) -> 0 | F25: {=_xll.DBR($A$6,C25,"Total Source",$E$1,$H$6,$H$5,"Amount")} -> -9707213.8 | G25: =IFERROR(D25-F25,0) -> 9707213.8 | H25: =IFERROR(F25/$F$12,0) -> -0.0060800374 | I25: =IFERROR((D25-F25)/ABS(F25),0) -> 1 | J25: {=_xll.DBR($A$6,C25,"Total Source",$E$1,$L$6,$L$5,"Amount")} -> -6390404.6 | K25: =IFERROR(D25-J25,0) -> 6390404.6 | L25: =IFERROR(J25/$J$12,0) -> -0.006361813 | M25: =IFERROR((D25-J25)/ABS(J25),0) -> 1 | N25: {=_xll.DBR($A$5,C25,$E$1,$O$6,$O$5,"Amount")} -> -6776107.2 | O25: =IFERROR(N25/$N$12,0) -> -0.0075148835 | Q25: {=_xll.DBR($A$5,C25,$E$1,$R$6,$R$5&"-YTD","Amount")} -> -1.0729489e+08 | R25: =IFERROR(Q25/$Q$12,0) -> -0.0096355894 | S25: {=_xll.DBR($A$6,C25,"Total Source",$E$1,$U$6,$U$5&"-YTD","Amount")} -> -1.0670786e+08 | T25: =IFERROR(Q25-S25,0) -> -587033.88 | U25: =IFERROR(S25/$S$12,0) -> -0.0071309054 | V25: =IFERROR((Q25-S25)/ABS(S25),0) -> -0.0055013182 | W25: {=_xll.DBR($A$6,C25,"Total Source",$E$1,$Y$6,$Y$5&"-YTD","Amount")} -> -1.1365329e+08 | X25: =IFERROR(Q25-W25,0) -> 6358394.1 | Y25: =IFERROR(W25/$W$12,0) -> -0.0093453226 | Z25: =IFERROR((Q25-W25)/ABS(W25),0) -> 0.055945537 | AA25: {=_xll.DBR($A$5,C25,$E$1,$AB$6,$AB$5&"-YTD","Amount")} -> -56525951 | AB25: =IFERROR(AA25/$AA$12,0) -> -0.0061636211
C26: - rent | D26: {=_xll.DBR($A$5,C26,$E$1,$E$6,$E$5,"Amount")} -> 1971604.6 | E26: =IFERROR(D26/$D$12,0) -> 0 | F26: {=_xll.DBR($A$6,C26,"Total Source",$E$1,$H$6,$H$5,"Amount")} -> -73501534 | G26: =IFERROR(D26-F26,0) -> 75473139 | H26: =IFERROR(F26/$F$12,0) -> -0.046037111 | I26: =IFERROR((D26-F26)/ABS(F26),0) -> 1.026824 | J26: {=_xll.DBR($A$6,C26,"Total Source",$E$1,$L$6,$L$5,"Amount")} -> -70171963 | K26: =IFERROR(D26-J26,0) -> 72143567 | L26: =IFERROR(J26/$J$12,0) -> -0.069858003 | M26: =IFERROR((D26-J26)/ABS(J26),0) -> 1.0280968 | N26: {=_xll.DBR($A$5,C26,$E$1,$O$6,$O$5,"Amount")} -> -38909701 | O26: =IFERROR(N26/$N$12,0) -> -0.043151895 | Q26: {=_xll.DBR($A$5,C26,$E$1,$R$6,$R$5&"-YTD","Amount")} -> -6.5899235e+08 | R26: =IFERROR(Q26/$Q$12,0) -> -0.059180635 | S26: {=_xll.DBR($A$6,C26,"Total Source",$E$1,$U$6,$U$5&"-YTD","Amount")} -> -7.4460349e+08 | T26: =IFERROR(Q26-S26,0) -> 85611136 | U26: =IFERROR(S26/$S$12,0) -> -0.049759195 | V26: =IFERROR((Q26-S26)/ABS(S26),0) -> 0.11497547 | W26: {=_xll.DBR($A$6,C26,"Total Source",$E$1,$Y$6,$Y$5&"-YTD","Amount")} -> -7.3309788e+08 | X26: =IFERROR(Q26-W26,0) -> 74105526 | Y26: =IFERROR(W26/$W$12,0) -> -0.060280142 | Z26: =IFERROR((Q26-W26)/ABS(W26),0) -> 0.10108545 | AA26: {=_xll.DBR($A$5,C26,$E$1,$AB$6,$AB$5&"-YTD","Amount")} -> -4.3313108e+08 | AB26: =IFERROR(AA26/$AA$12,0) -> -0.047228854
C27: - operating leases | D27: {=_xll.DBR($A$5,C27,$E$1,$E$6,$E$5,"Amount")} -> 0 | E27: =IFERROR(D27/$D$12,0) -> 0 | F27: {=_xll.DBR($A$6,C27,"Total Source",$E$1,$H$6,$H$5,"Amount")} -> 0 | G27: =IFERROR(D27-F27,0) -> 0 | H27: =IFERROR(F27/$F$12,0) -> 0 | I27: =IFERROR((D27-F27)/ABS(F27),0) -> 0 | J27: {=_xll.DBR($A$6,C27,"Total Source",$E$1,$L$6,$L$5,"Amount")} -> 0 | K27: =IFERROR(D27-J27,0) -> 0 | L27: =IFERROR(J27/$J$12,0) -> 0 | M27: =IFERROR((D27-J27)/ABS(J27),0) -> 0 | N27: {=_xll.DBR($A$5,C27,$E$1,$O$6,$O$5,"Amount")} -> 0 | O27: =IFERROR(N27/$N$12,0) -> 0 | Q27: {=_xll.DBR($A$5,C27,$E$1,$R$6,$R$5&"-YTD","Amount")} -> 0 | R27: =IFERROR(Q27/$Q$12,0) -> 0 | S27: {=_xll.DBR($A$6,C27,"Total Source",$E$1,$U$6,$U$5&"-YTD","Amount")} -> 0 | T27: =IFERROR(Q27-S27,0) -> 0 | U27: =IFERROR(S27/$S$12,0) -> 0 | V27: =IFERROR((Q27-S27)/ABS(S27),0) -> 0 | W27: {=_xll.DBR($A$6,C27,"Total Source",$E$1,$Y$6,$Y$5&"-YTD","Amount")} -> 0 | X27: =IFERROR(Q27-W27,0) -> 0 | Y27: =IFERROR(W27/$W$12,0) -> 0 | Z27: =IFERROR((Q27-W27)/ABS(W27),0) -> 0 | AA27: {=_xll.DBR($A$5,C27,$E$1,$AB$6,$AB$5&"-YTD","Amount")} -> 0 | AB27: =IFERROR(AA27/$AA$12,0) -> 0
C28: - repairs and maintenance | D28: {=_xll.DBR($A$5,C28,$E$1,$E$6,$E$5,"Amount")} -> 0 | E28: =IFERROR(D28/$D$12,0) -> 0 | F28: {=_xll.DBR($A$6,C28,"Total Source",$E$1,$H$6,$H$5,"Amount")} -> -2281222.2 | G28: =IFERROR(D28-F28,0) -> 2281222.2 | H28: =IFERROR(F28/$F$12,0) -> -0.0014288257 | I28: =IFERROR((D28-F28)/ABS(F28),0) -> 1 | J28: {=_xll.DBR($A$6,C28,"Total Source",$E$1,$L$6,$L$5,"Amount")} -> -2096339.2 | K28: =IFERROR(D28-J28,0) -> 2096339.2 | L28: =IFERROR(J28/$J$12,0) -> -0.0020869599 | M28: =IFERROR((D28-J28)/ABS(J28),0) -> 1 | N28: {=_xll.DBR($A$5,C28,$E$1,$O$6,$O$5,"Amount")} -> -1967745.1 | O28: =IFERROR(N28/$N$12,0) -> -0.0021822817 | Q28: {=_xll.DBR($A$5,C28,$E$1,$R$6,$R$5&"-YTD","Amount")} -> -28391621 | R28: =IFERROR(Q28/$Q$12,0) -> -0.002549702 | S28: {=_xll.DBR($A$6,C28,"Total Source",$E$1,$U$6,$U$5&"-YTD","Amount")} -> -25028325 | T28: =IFERROR(Q28-S28,0) -> -3363296 | U28: =IFERROR(S28/$S$12,0) -> -0.0016725536 | V28: =IFERROR((Q28-S28)/ABS(S28),0) -> -0.13437959 | W28: {=_xll.DBR($A$6,C28,"Total Source",$E$1,$Y$6,$Y$5&"-YTD","Amount")} -> -28975882 | X28: =IFERROR(Q28-W28,0) -> 584261.15 | Y28: =IFERROR(W28/$W$12,0) -> -0.0023825881 | Z28: =IFERROR((Q28-W28)/ABS(W28),0) -> 0.020163706 | AA28: {=_xll.DBR($A$5,C28,$E$1,$AB$6,$AB$5&"-YTD","Amount")} -> -19868645 | AB28: =IFERROR(AA28/$AA$12,0) -> -0.0021664881
C29: - IT maintenance | D29: {=_xll.DBR($A$5,C29,$E$1,$E$6,$E$5,"Amount")} -> 0 | E29: =IFERROR(D29/$D$12,0) -> 0 | F29: {=_xll.DBR($A$6,C29,"Total Source",$E$1,$H$6,$H$5,"Amount")} -> -1430938.1 | G29: =IFERROR(D29-F29,0) -> 1430938.1 | H29: =IFERROR(F29/$F$12,0) -> -0.00089625687 | I29: =IFERROR((D29-F29)/ABS(F29),0) -> 1 | J29: {=_xll.DBR($A$6,C29,"Total Source",$E$1,$L$6,$L$5,"Amount")} -> -1178034.2 | K29: =IFERROR(D29-J29,0) -> 1178034.2 | L29: =IFERROR(J29/$J$12,0) -> -0.0011727635 | M29: =IFERROR((D29-J29)/ABS(J29),0) -> 1 | N29: {=_xll.DBR($A$5,C29,$E$1,$O$6,$O$5,"Amount")} -> -909514.78 | O29: =IFERROR(N29/$N$12,0) -> -0.0010086761 | Q29: {=_xll.DBR($A$5,C29,$E$1,$R$6,$R$5&"-YTD","Amount")} -> -10762982 | R29: =IFERROR(Q29/$Q$12,0) -> -0.00096656677 | S29: {=_xll.DBR($A$6,C29,"Total Source",$E$1,$U$6,$U$5&"-YTD","Amount")} -> -14013228 | T29: =IFERROR(Q29-S29,0) -> 3250245.5 | U29: =IFERROR(S29/$S$12,0) -> -0.000936454 | V29: =IFERROR((Q29-S29)/ABS(S29),0) -> 0.23194125 | W29: {=_xll.DBR($A$6,C29,"Total Source",$E$1,$Y$6,$Y$5&"-YTD","Amount")} -> -11941016 | X29: =IFERROR(Q29-W29,0) -> 1178034.2 | Y29: =IFERROR(W29/$W$12,0) -> -0.0009818691 | Z29: =IFERROR((Q29-W29)/ABS(W29),0) -> 0.098654433 | AA29: {=_xll.DBR($A$5,C29,$E$1,$AB$6,$AB$5&"-YTD","Amount")} -> -8153699.4 | AB29: =IFERROR(AA29/$AA$12,0) -> -0.00088908392
C30: - retail asset depreciation | D30: {=_xll.DBR($A$5,C30,$E$1,$E$6,$E$5,"Amount")} -> -1.6814106e+08 | E30: =IFERROR(D30/$D$12,0) -> 0 | F30: {=_xll.DBR($A$6,C30,"Total Source",$E$1,$H$6,$H$5,"Amount")} -> -13269642 | J30: {=_xll.DBR($A$6,C30,"Total Source",$E$1,$L$6,$L$5,"Amount")} -> -13467895 | N30: {=_xll.DBR($A$5,C30,$E$1,$O$6,$O$5,"Amount")} -> -18849778 | Q30: {=_xll.DBR($A$5,C30,$E$1,$R$6,$R$5&"-YTD","Amount")} -> -2.621374e+08 | S30: {=_xll.DBR($A$6,C30,"Total Source",$E$1,$U$6,$U$5&"-YTD","Amount")} -> -1.2484726e+08 | W30: {=_xll.DBR($A$6,C30,"Total Source",$E$1,$Y$6,$Y$5&"-YTD","Amount")} -> -1.0432158e+08 | AA30: {=_xll.DBR($A$5,C30,$E$1,$AB$6,$AB$5&"-YTD","Amount")} -> -1.3233858e+08
C31: - retail asset profit/(loss) on sales | D31: {=_xll.DBR($A$5,C31,$E$1,$E$6,$E$5,"Amount")} -> 0 | E31: =IFERROR(D31/$D$12,0) -> 0 | F31: {=_xll.DBR($A$6,C31,"Total Source",$E$1,$H$6,$H$5,"Amount")} -> 0 | G31: =IFERROR(D31-F31,0) -> 0 | H31: =IFERROR(F31/$F$12,0) -> 0 | I31: =IFERROR((D31-F31)/ABS(F31),0) -> 0 | J31: {=_xll.DBR($A$6,C31,"Total Source",$E$1,$L$6,$L$5,"Amount")} -> 0 | K31: =IFERROR(D31-J31,0) -> 0 | L31: =IFERROR(J31/$J$12,0) -> 0 | M31: =IFERROR((D31-J31)/ABS(J31),0) -> 0 | N31: {=_xll.DBR($A$5,C31,$E$1,$O$6,$O$5,"Amount")} -> 0 | O31: =IFERROR(N31/$N$12,0) -> 0 | Q31: {=_xll.DBR($A$5,C31,$E$1,$R$6,$R$5&"-YTD","Amount")} -> 0 | R31: =IFERROR(Q31/$Q$12,0) -> 0 | S31: {=_xll.DBR($A$6,C31,"Total Source",$E$1,$U$6,$U$5&"-YTD","Amount")} -> 0 | T31: =IFERROR(Q31-S31,0) -> 0 | U31: =IFERROR(S31/$S$12,0) -> 0 | V31: =IFERROR((Q31-S31)/ABS(S31),0) -> 0 | W31: {=_xll.DBR($A$6,C31,"Total Source",$E$1,$Y$6,$Y$5&"-YTD","Amount")} -> 0 | X31: =IFERROR(Q31-W31,0) -> 0 | Y31: =IFERROR(W31/$W$12,0) -> 0 | Z31: =IFERROR((Q31-W31)/ABS(W31),0) -> 0 | AA31: {=_xll.DBR($A$5,C31,$E$1,$AB$6,$AB$5&"-YTD","Amount")} -> 0 | AB31: =IFERROR(AA31/$AA$12,0) -> 0
C32: - credit card charges | D32: {=_xll.DBR($A$5,C32,$E$1,$E$6,$E$5,"Amount")} -> 0 | E32: =IFERROR(D32/$D$12,0) -> 0 | F32: {=_xll.DBR($A$6,C32,"Total Source",$E$1,$H$6,$H$5,"Amount")} -> -0.0096827109 | G32: =IFERROR(D32-F32,0) -> 0.0096827109 | H32: =IFERROR(F32/$F$12,0) -> -6.0646902e-12 | I32: =IFERROR((D32-F32)/ABS(F32),0) -> 1 | J32: {=_xll.DBR($A$6,C32,"Total Source",$E$1,$L$6,$L$5,"Amount")} -> -65397086 | K32: =IFERROR(D32-J32,0) -> 65397086 | L32: =IFERROR(J32/$J$12,0) -> -0.06510449 | M32: =IFERROR((D32-J32)/ABS(J32),0) -> 1 | N32: {=_xll.DBR($A$5,C32,$E$1,$O$6,$O$5,"Amount")} -> -23955976 | O32: =IFERROR(N32/$N$12,0) -> -0.026567816 | Q32: {=_xll.DBR($A$5,C32,$E$1,$R$6,$R$5&"-YTD","Amount")} -> -5.6064384e+08 | R32: =IFERROR(Q32/$Q$12,0) -> -0.050348472 | S32: {=_xll.DBR($A$6,C32,"Total Source",$E$1,$U$6,$U$5&"-YTD","Amount")} -> -1.6337934e+08 | T32: =IFERROR(Q32-S32,0) -> -3.972645e+08 | U32: =IFERROR(S32/$S$12,0) -> -0.010918058 | V32: =IFERROR((Q32-S32)/ABS(S32),0) -> -2.4315467 | W32: {=_xll.DBR($A$6,C32,"Total Source",$E$1,$Y$6,$Y$5&"-YTD","Amount")} -> -6.3654905e+08 | X32: =IFERROR(Q32-W32,0) -> 75905214 | Y32: =IFERROR(W32/$W$12,0) -> -0.05234126 | Z32: =IFERROR((Q32-W32)/ABS(W32),0) -> 0.11924488 | AA32: {=_xll.DBR($A$5,C32,$E$1,$AB$6,$AB$5&"-YTD","Amount")} -> -1.9539404e+08 | AB32: =IFERROR(AA32/$AA$12,0) -> -0.021305875
C33: - utilities | D33: {=_xll.DBR($A$5,C33,$E$1,$E$6,$E$5,"Amount")} -> 0 | E33: =IFERROR(D33/$D$12,0) -> 0 | F33: {=_xll.DBR($A$6,C33,"Total Source",$E$1,$H$6,$H$5,"Amount")} -> -13265821 | G33: =IFERROR(D33-F33,0) -> 13265821 | H33: =IFERROR(F33/$F$12,0) -> -0.0083089434 | I33: =IFERROR((D33-F33)/ABS(F33),0) -> 1 | J33: {=_xll.DBR($A$6,C33,"Total Source",$E$1,$L$6,$L$5,"Amount")} -> -10430667 | K33: =IFERROR(D33-J33,0) -> 10430667 | L33: =IFERROR(J33/$J$12,0) -> -0.010383999 | M33: =IFERROR((D33-J33)/ABS(J33),0) -> 1 | N33: {=_xll.DBR($A$5,C33,$E$1,$O$6,$O$5,"Amount")} -> -11507671 | O33: =IFERROR(N33/$N$12,0) -> -0.012762314 | Q33: {=_xll.DBR($A$5,C33,$E$1,$R$6,$R$5&"-YTD","Amount")} -> -1.2433001e+08 | R33: =IFERROR(Q33/$Q$12,0) -> -0.011165423 | S33: {=_xll.DBR($A$6,C33,"Total Source",$E$1,$U$6,$U$5&"-YTD","Amount")} -> -1.5424633e+08 | T33: =IFERROR(Q33-S33,0) -> 29916325 | U33: =IFERROR(S33/$S$12,0) -> -0.010307732 | V33: =IFERROR((Q33-S33)/ABS(S33),0) -> 0.19395162 | W33: {=_xll.DBR($A$6,C33,"Total Source",$E$1,$Y$6,$Y$5&"-YTD","Amount")} -> -1.3200338e+08 | X33: =IFERROR(Q33-W33,0) -> 7673371.5 | Y33: =IFERROR(W33/$W$12,0) -> -0.010854188 | Z33: =IFERROR((Q33-W33)/ABS(W33),0) -> 0.058130115 | AA33: {=_xll.DBR($A$5,C33,$E$1,$AB$6,$AB$5&"-YTD","Amount")} -> -1.0790551e+08 | AB33: =IFERROR(AA33/$AA$12,0) -> -0.011766077
C34: - printing and stationery | D34: {=_xll.DBR($A$5,C34,$E$1,$E$6,$E$5,"Amount")} -> 0 | E34: =IFERROR(D34/$D$12,0) -> 0 | F34: {=_xll.DBR($A$6,C34,"Total Source",$E$1,$H$6,$H$5,"Amount")} -> -975054.11 | G34: =IFERROR(D34-F34,0) -> 975054.11 | H34: =IFERROR(F34/$F$12,0) -> -0.00061071751 | I34: =IFERROR((D34-F34)/ABS(F34),0) -> 1 | J34: {=_xll.DBR($A$6,C34,"Total Source",$E$1,$L$6,$L$5,"Amount")} -> -842256.11 | K34: =IFERROR(D34-J34,0) -> 842256.11 | L34: =IFERROR(J34/$J$12,0) -> -0.00083848773 | M34: =IFERROR((D34-J34)/ABS(J34),0) -> 1 | N34: {=_xll.DBR($A$5,C34,$E$1,$O$6,$O$5,"Amount")} -> -668933.69 | O34: =IFERROR(N34/$N$12,0) -> -0.00074186529 | Q34: {=_xll.DBR($A$5,C34,$E$1,$R$6,$R$5&"-YTD","Amount")} -> -7045582.4 | R34: =IFERROR(Q34/$Q$12,0) -> -0.00063272667 | S34: {=_xll.DBR($A$6,C34,"Total Source",$E$1,$U$6,$U$5&"-YTD","Amount")} -> -10699395 | T34: =IFERROR(Q34-S34,0) -> 3653812.8 | U34: =IFERROR(S34/$S$12,0) -> -0.00071500241 | V34: =IFERROR((Q34-S34)/ABS(S34),0) -> 0.34149713 | W34: {=_xll.DBR($A$6,C34,"Total Source",$E$1,$Y$6,$Y$5&"-YTD","Amount")} -> -7788848.5 | X34: =IFERROR(Q34-W34,0) -> 743266.05 | Y34: =IFERROR(W34/$W$12,0) -> -0.00064045048 | Z34: =IFERROR((Q34-W34)/ABS(W34),0) -> 0.095426949 | AA34: {=_xll.DBR($A$5,C34,$E$1,$AB$6,$AB$5&"-YTD","Amount")} -> -7194455.6 | AB34: =IFERROR(AA34/$AA$12,0) -> -0.00078448744
C35: - communications | D35: {=_xll.DBR($A$5,C35,$E$1,$E$6,$E$5,"Amount")} -> 0 | E35: =IFERROR(D35/$D$12,0) -> 0 | F35: {=_xll.DBR($A$6,C35,"Total Source",$E$1,$H$6,$H$5,"Amount")} -> -344635.91 | G35: =IFERROR(D35-F35,0) -> 344635.91 | H35: =IFERROR(F35/$F$12,0) -> -0.00021586001 | I35: =IFERROR((D35-F35)/ABS(F35),0) -> 1 | J35: {=_xll.DBR($A$6,C35,"Total Source",$E$1,$L$6,$L$5,"Amount")} -> -301635.58 | K35: =IFERROR(D35-J35,0) -> 301635.58 | L35: =IFERROR(J35/$J$12,0) -> -0.00030028602 | M35: =IFERROR((D35-J35)/ABS(J35),0) -> 1 | N35: {=_xll.DBR($A$5,C35,$E$1,$O$6,$O$5,"Amount")} -> -352239.45 | O35: =IFERROR(N35/$N$12,0) -> -0.00039064294 | Q35: {=_xll.DBR($A$5,C35,$E$1,$R$6,$R$5&"-YTD","Amount")} -> -3329846.5 | R35: =IFERROR(Q35/$Q$12,0) -> -0.00029903599 | S35: {=_xll.DBR($A$6,C35,"Total Source",$E$1,$U$6,$U$5&"-YTD","Amount")} -> -3785456.1 | T35: =IFERROR(Q35-S35,0) -> 455609.64 | U35: =IFERROR(S35/$S$12,0) -> -0.00025296853 | V35: =IFERROR((Q35-S35)/ABS(S35),0) -> 0.12035792 | W35: {=_xll.DBR($A$6,C35,"Total Source",$E$1,$Y$6,$Y$5&"-YTD","Amount")} -> -3735253.9 | X35: =IFERROR(Q35-W35,0) -> 405407.39 | Y35: =IFERROR(W35/$W$12,0) -> -0.00030713721 | Z35: =IFERROR((Q35-W35)/ABS(W35),0) -> 0.10853543 | AA35: {=_xll.DBR($A$5,C35,$E$1,$AB$6,$AB$5&"-YTD","Amount")} -> -2429962 | AB35: =IFERROR(AA35/$AA$12,0) -> -0.0002649644
C36: - travel | D36: {=_xll.DBR($A$5,C36,$E$1,$E$6,$E$5,"Amount")} -> 0 | E36: =IFERROR(D36/$D$12,0) -> 0 | F36: {=_xll.DBR($A$6,C36,"Total Source",$E$1,$H$6,$H$5,"Amount")} -> -174185.25 | G36: =IFERROR(D36-F36,0) -> 174185.25 | H36: =IFERROR(F36/$F$12,0) -> -0.00010909957 | I36: =IFERROR((D36-F36)/ABS(F36),0) -> 1 | J36: {=_xll.DBR($A$6,C36,"Total Source",$E$1,$L$6,$L$5,"Amount")} -> -174185.25 | K36: =IFERROR(D36-J36,0) -> 174185.25 | L36: =IFERROR(J36/$J$12,0) -> -0.00017340592 | M36: =IFERROR((D36-J36)/ABS(J36),0) -> 1 | N36: {=_xll.DBR($A$5,C36,$E$1,$O$6,$O$5,"Amount")} -> -420229.32 | O36: =IFERROR(N36/$N$12,0) -> -0.00046604551 | Q36: {=_xll.DBR($A$5,C36,$E$1,$R$6,$R$5&"-YTD","Amount")} -> -3463101.5 | R36: =IFERROR(Q36/$Q$12,0) -> -0.00031100292 | S36: {=_xll.DBR($A$6,C36,"Total Source",$E$1,$U$6,$U$5&"-YTD","Amount")} -> -2535042 | T36: =IFERROR(Q36-S36,0) -> -928059.51 | U36: =IFERROR(S36/$S$12,0) -> -0.00016940781 | V36: =IFERROR((Q36-S36)/ABS(S36),0) -> -0.36609236 | W36: {=_xll.DBR($A$6,C36,"Total Source",$E$1,$Y$6,$Y$5&"-YTD","Amount")} -> -3607968.3 | X36: =IFERROR(Q36-W36,0) -> 144866.76 | Y36: =IFERROR(W36/$W$12,0) -> -0.00029667094 | Z36: =IFERROR((Q36-W36)/ABS(W36),0) -> 0.040151893 | AA36: {=_xll.DBR($A$5,C36,$E$1,$AB$6,$AB$5&"-YTD","Amount")} -> -2388083.6 | AB36: =IFERROR(AA36/$AA$12,0) -> -0.00026039797
C37: - cleaning | D37: {=_xll.DBR($A$5,C37,$E$1,$E$6,$E$5,"Amount")} -> 0 | E37: =IFERROR(D37/$D$12,0) -> 0 | F37: {=_xll.DBR($A$6,C37,"Total Source",$E$1,$H$6,$H$5,"Amount")} -> -5619731.8 | G37: =IFERROR(D37-F37,0) -> 5619731.8 | H37: =IFERROR(F37/$F$12,0) -> -0.003519875 | I37: =IFERROR((D37-F37)/ABS(F37),0) -> 1 | J37: {=_xll.DBR($A$6,C37,"Total Source",$E$1,$L$6,$L$5,"Amount")} -> -4994150.7 | K37: =IFERROR(D37-J37,0) -> 4994150.7 | L37: =IFERROR(J37/$J$12,0) -> -0.0049718061 | M37: =IFERROR((D37-J37)/ABS(J37),0) -> 1 | N37: {=_xll.DBR($A$5,C37,$E$1,$O$6,$O$5,"Amount")} -> -3492549.3 | O37: =IFERROR(N37/$N$12,0) -> -0.0038733302 | Q37: {=_xll.DBR($A$5,C37,$E$1,$R$6,$R$5&"-YTD","Amount")} -> -45393788 | R37: =IFERROR(Q37/$Q$12,0) -> -0.0040765772 | S37: {=_xll.DBR($A$6,C37,"Total Source",$E$1,$U$6,$U$5&"-YTD","Amount")} -> -59124901 | T37: =IFERROR(Q37-S37,0) -> 13731112 | U37: =IFERROR(S37/$S$12,0) -> -0.0039511062 | V37: =IFERROR((Q37-S37)/ABS(S37),0) -> 0.23223908 | W37: {=_xll.DBR($A$6,C37,"Total Source",$E$1,$Y$6,$Y$5&"-YTD","Amount")} -> -51112312 | X37: =IFERROR(Q37-W37,0) -> 5718523.8 | Y37: =IFERROR(W37/$W$12,0) -> -0.0042027913 | Z37: =IFERROR((Q37-W37)/ABS(W37),0) -> 0.11188153 | AA37: {=_xll.DBR($A$5,C37,$E$1,$AB$6,$AB$5&"-YTD","Amount")} -> -30709327 | AB37: =IFERROR(AA37/$AA$12,0) -> -0.0033485621
C38: - security | D38: {=_xll.DBR($A$5,C38,$E$1,$E$6,$E$5,"Amount")} -> 0 | E38: =IFERROR(D38/$D$12,0) -> 0 | F38: {=_xll.DBR($A$6,C38,"Total Source",$E$1,$H$6,$H$5,"Amount")} -> -4297166.4 | G38: =IFERROR(D38-F38,0) -> 4297166.4 | H38: =IFERROR(F38/$F$12,0) -> -0.0026914966 | I38: =IFERROR((D38-F38)/ABS(F38),0) -> 1 | J38: {=_xll.DBR($A$6,C38,"Total Source",$E$1,$L$6,$L$5,"Amount")} -> -3513736.5 | K38: =IFERROR(D38-J38,0) -> 3513736.5 | L38: =IFERROR(J38/$J$12,0) -> -0.0034980155 | M38: =IFERROR((D38-J38)/ABS(J38),0) -> 1 | N38: {=_xll.DBR($A$5,C38,$E$1,$O$6,$O$5,"Amount")} -> -4433565.2 | O38: =IFERROR(N38/$N$12,0) -> -0.004916942 | Q38: {=_xll.DBR($A$5,C38,$E$1,$R$6,$R$5&"-YTD","Amount")} -> -38382699 | R38: =IFERROR(Q38/$Q$12,0) -> -0.0034469481 | S38: {=_xll.DBR($A$6,C38,"Total Source",$E$1,$U$6,$U$5&"-YTD","Amount")} -> -45356864 | T38: =IFERROR(Q38-S38,0) -> 6974165.5 | U38: =IFERROR(S38/$S$12,0) -> -0.0030310374 | V38: =IFERROR((Q38-S38)/ABS(S38),0) -> 0.15376207 | W38: {=_xll.DBR($A$6,C38,"Total Source",$E$1,$Y$6,$Y$5&"-YTD","Amount")} -> -41684800 | X38: =IFERROR(Q38-W38,0) -> 3302101.2 | Y38: =IFERROR(W38/$W$12,0) -> -0.0034275991 | Z38: =IFERROR((Q38-W38)/ABS(W38),0) -> 0.079215954 | AA38: {=_xll.DBR($A$5,C38,$E$1,$AB$6,$AB$5&"-YTD","Amount")} -> -29519673 | AB38: =IFERROR(AA38/$AA$12,0) -> -0.0032188416
C39: - insurance exp. | D39: {=_xll.DBR($A$5,C39,$E$1,$E$6,$E$5,"Amount")} -> -21018.64 | E39: =IFERROR(D39/$D$12,0) -> 0 | F39: {=_xll.DBR($A$6,C39,"Total Source",$E$1,$H$6,$H$5,"Amount")} -> -1874357.7 | G39: =IFERROR(D39-F39,0) -> 1853339.1 | H39: =IFERROR(F39/$F$12,0) -> -0.0011739893 | I39: =IFERROR((D39-F39)/ABS(F39),0) -> 0.98878622 | J39: {=_xll.DBR($A$6,C39,"Total Source",$E$1,$L$6,$L$5,"Amount")} -> -1416721.2 | K39: =IFERROR(D39-J39,0) -> 1395702.5 | L39: =IFERROR(J39/$J$12,0) -> -0.0014103826 | M39: =IFERROR((D39-J39)/ABS(J39),0) -> 0.98516388 | N39: {=_xll.DBR($A$5,C39,$E$1,$O$6,$O$5,"Amount")} -> -930520.53 | O39: =IFERROR(N39/$N$12,0) -> -0.0010319721 | Q39: {=_xll.DBR($A$5,C39,$E$1,$R$6,$R$5&"-YTD","Amount")} -> -15875457 | R39: =IFERROR(Q39/$Q$12,0) -> -0.0014256913 | S39: {=_xll.DBR($A$6,C39,"Total Source",$E$1,$U$6,$U$5&"-YTD","Amount")} -> -20804000 | T39: =IFERROR(Q39-S39,0) -> 4928542.7 | U39: =IFERROR(S39/$S$12,0) -> -0.0013902571 | V39: =IFERROR((Q39-S39)/ABS(S39),0) -> 0.23690361 | W39: {=_xll.DBR($A$6,C39,"Total Source",$E$1,$Y$6,$Y$5&"-YTD","Amount")} -> -17236682 | X39: =IFERROR(Q39-W39,0) -> 1361225.1 | Y39: =IFERROR(W39/$W$12,0) -> -0.0014173137 | Z39: =IFERROR((Q39-W39)/ABS(W39),0) -> 0.078972571 | AA39: {=_xll.DBR($A$5,C39,$E$1,$AB$6,$AB$5&"-YTD","Amount")} -> -9802867.3 | AB39: =IFERROR(AA39/$AA$12,0) -> -0.0010689101
C40: - external services | D40: {=_xll.DBR($A$5,C40,$E$1,$E$6,$E$5,"Amount")} -> -6.9999984e-05 | E40: =IFERROR(D40/$D$12,0) -> 0 | F40: {=_xll.DBR($A$6,C40,"Total Source",$E$1,$H$6,$H$5,"Amount")} -> -4039407.9 | G40: =IFERROR(D40-F40,0) -> 4039407.9 | H40: =IFERROR(F40/$F$12,0) -> -0.0025300515 | I40: =IFERROR((D40-F40)/ABS(F40),0) -> 1 | J40: {=_xll.DBR($A$6,C40,"Total Source",$E$1,$L$6,$L$5,"Amount")} -> -2424671.8 | K40: =IFERROR(D40-J40,0) -> 2424671.8 | L40: =IFERROR(J40/$J$12,0) -> -0.0024138234 | M40: =IFERROR((D40-J40)/ABS(J40),0) -> 1 | N40: {=_xll.DBR($A$5,C40,$E$1,$O$6,$O$5,"Amount")} -> -2300979.2 | O40: =IFERROR(N40/$N$12,0) -> -0.0025518472 | Q40: {=_xll.DBR($A$5,C40,$E$1,$R$6,$R$5&"-YTD","Amount")} -> -30644394 | R40: =IFERROR(Q40/$Q$12,0) -> -0.0027520118 | S40: {=_xll.DBR($A$6,C40,"Total Source",$E$1,$U$6,$U$5&"-YTD","Amount")} -> -45184134 | T40: =IFERROR(Q40-S40,0) -> 14539740 | U40: =IFERROR(S40/$S$12,0) -> -0.0030194945 | V40: =IFERROR((Q40-S40)/ABS(S40),0) -> 0.32178861 | W40: {=_xll.DBR($A$6,C40,"Total Source",$E$1,$Y$6,$Y$5&"-YTD","Amount")} -> -35443541 | X40: =IFERROR(Q40-W40,0) -> 4799146.8 | Y40: =IFERROR(W40/$W$12,0) -> -0.0029144017 | Z40: =IFERROR((Q40-W40)/ABS(W40),0) -> 0.13540258 | AA40: {=_xll.DBR($A$5,C40,$E$1,$AB$6,$AB$5&"-YTD","Amount")} -> -23892033 | AB40: =IFERROR(AA40/$AA$12,0) -> -0.0026052006
C41: - call center expenses | D41: {=_xll.DBR($A$5,C41,$E$1,$E$6,$E$5,"Amount")} -> 0 | E41: =IFERROR(D41/$D$12,0) -> 0 | F41: {=_xll.DBR($A$6,C41,"Total Source",$E$1,$H$6,$H$5,"Amount")} -> -2856551 | G41: =IFERROR(D41-F41,0) -> 2856551 | H41: =IFERROR(F41/$F$12,0) -> -0.0017891784 | I41: =IFERROR((D41-F41)/ABS(F41),0) -> 1 | J41: {=_xll.DBR($A$6,C41,"Total Source",$E$1,$L$6,$L$5,"Amount")} -> -2888684.9 | K41: =IFERROR(D41-J41,0) -> 2888684.9 | L41: =IFERROR(J41/$J$12,0) -> -0.0028757605 | M41: =IFERROR((D41-J41)/ABS(J41),0) -> 1 | N41: {=_xll.DBR($A$5,C41,$E$1,$O$6,$O$5,"Amount")} -> -1580879.6 | O41: =IFERROR(N41/$N$12,0) -> -0.0017532376 | Q41: {=_xll.DBR($A$5,C41,$E$1,$R$6,$R$5&"-YTD","Amount")} -> -21693817 | R41: =IFERROR(Q41/$Q$12,0) -> -0.0019482075 | S41: {=_xll.DBR($A$6,C41,"Total Source",$E$1,$U$6,$U$5&"-YTD","Amount")} -> -26898712 | T41: =IFERROR(Q41-S41,0) -> 5204894.9 | U41: =IFERROR(S41/$S$12,0) -> -0.0017975449 | V41: =IFERROR((Q41-S41)/ABS(S41),0) -> 0.19349978 | W41: {=_xll.DBR($A$6,C41,"Total Source",$E$1,$Y$6,$Y$5&"-YTD","Amount")} -> -25092442 | X41: =IFERROR(Q41-W41,0) -> 3398625.3 | Y41: =IFERROR(W41/$W$12,0) -> -0.0020632661 | Z41: =IFERROR((Q41-W41)/ABS(W41),0) -> 0.13544418 | AA41: {=_xll.DBR($A$5,C41,$E$1,$AB$6,$AB$5&"-YTD","Amount")} -> -14483009 | AB41: =IFERROR(AA41/$AA$12,0) -> -0.0015792353
C42: - rental car expenses | D42: {=_xll.DBR($A$5,C42,$E$1,$E$6,$E$5,"Amount")} -> 0 | E42: =IFERROR(D42/$D$12,0) -> 0 | F42: {=_xll.DBR($A$6,C42,"Total Source",$E$1,$H$6,$H$5,"Amount")} -> -1592354 | G42: =IFERROR(D42-F42,0) -> 1592354 | H42: =IFERROR(F42/$F$12,0) -> -0.00099735847 | I42: =IFERROR((D42-F42)/ABS(F42),0) -> 1 | J42: {=_xll.DBR($A$6,C42,"Total Source",$E$1,$L$6,$L$5,"Amount")} -> -1361644.1 | K42: =IFERROR(D42-J42,0) -> 1361644.1 | L42: =IFERROR(J42/$J$12,0) -> -0.0013555519 | M42: =IFERROR((D42-J42)/ABS(J42),0) -> 1 | N42: {=_xll.DBR($A$5,C42,$E$1,$O$6,$O$5,"Amount")} -> -1350474.2 | O42: =IFERROR(N42/$N$12,0) -> -0.0014977119 | Q42: {=_xll.DBR($A$5,C42,$E$1,$R$6,$R$5&"-YTD","Amount")} -> -10802797 | R42: =IFERROR(Q42/$Q$12,0) -> -0.00097014232 | S42: {=_xll.DBR($A$6,C42,"Total Source",$E$1,$U$6,$U$5&"-YTD","Amount")} -> -13583836 | T42: =IFERROR(Q42-S42,0) -> 2781038.9 | U42: =IFERROR(S42/$S$12,0) -> -0.00090775928 | V42: =IFERROR((Q42-S42)/ABS(S42),0) -> 0.20473149 | W42: {=_xll.DBR($A$6,C42,"Total Source",$E$1,$Y$6,$Y$5&"-YTD","Amount")} -> -12298086 | X42: =IFERROR(Q42-W42,0) -> 1495288.8 | Y42: =IFERROR(W42/$W$12,0) -> -0.0010112297 | Z42: =IFERROR((Q42-W42)/ABS(W42),0) -> 0.12158712 | AA42: {=_xll.DBR($A$5,C42,$E$1,$AB$6,$AB$5&"-YTD","Amount")} -> -9961611 | AB42: =IFERROR(AA42/$AA$12,0) -> -0.0010862196
...

Sheet COST
C1: Masraf Merkezi | D1: =PL!E1 -> Koçtaş Total | E1: Dönem | F1: =PL!G1 -> 2024-11
A5: tm1:Fiili | C5: Dönem | D5: =PL!E5 -> 2024-11 | E5: Dönem | G5: =PL!H5 -> 2024-11 | H5: Dönem | J5: =PL!L5 -> 2024-11 | K5: Dönem | L5: =PL!O5 -> 2023-11 | N5: Dönem | O5: =PL!R5 -> 2024-11 | P5: Dönem | R5: =PL!U5 -> 2024-11 | S5: Dönem | U5: =PL!Y5 -> 2024-11 | V5: Dönem | W5: =PL!AB5 -> 2023-11
A6: tm1:Genel Giderler | C6: Fiili Senaryo | D6: =PL!E6 -> Fiili | E6: Bütçe Versiyonu | G6: =PL!H6 -> Budget 2024 | Arşiv | H6: Forecast Versiyonu | J6: =PL!L6 -> Forecast 9+3 2024 | Arşiv | K6: Fiili Senaryo | L6: =PL!O6 -> Fiili | N6: Fiili Senaryo | O6: =PL!R6 -> Fiili | P6: Bütçe Versiyonu | R6: =PL!U6 -> Budget 2024 | Arşiv | S6: Forecast Versiyonu | U6: =PL!Y6 -> Forecast 9+3 2024 | Arşiv | V6: Fiili Senaryo | W6: =PL!AB6 -> Fiili
C8: MONTHLY | E8: MONTHLY | H8: MONTHLY | K8: MONTHLY | N8: YTD | P8: YTD | S8: YTD | V8: YTD
C9: Actual | E9: =G6 -> Budget 2024 | Arşiv | F9: Var. Actual | G9: Actual vs Budget (%) | H9: =J6 -> Forecast 9+3 2024 | Arşiv | I9: Var. Actual | J9: Actual vs Forecast (%) | K9: LY | L9: Actual vs LY (%) | N9: Actual | P9: =R6 -> Budget 2024 | Arşiv | Q9: Var. Actual | R9: Actual vs Budget (%) | S9: =U6 -> Forecast 9+3 2024 | Arşiv | T9: Var. Actual | U9: Actual vs Forecast (%) | V9: LY | W9: Actual vs LY (%)
B10: Staff | C10: {=_xll.DBR($A$5,B10,$D$1,$D$6,$D$5,"Karşlılık Sonrası - Aylık")} -> 11795368 | E10: {=_xll.DBR($A$6,B10,$D$1,"Departman Toplam",$G$6,$G$5,"Amount Cost")} -> 2.206802e+08 | F10: =IFERROR(C10-E10,0) -> -2.0888484e+08 | G10: =IFERROR((C10-E10)/ABS(E10),0) -> -0.94654995 | H10: {=_xll.DBR($A$6,B10,$D$1,"Departman Toplam",$J$6,$J$5,"Amount Cost")} -> 1.9666299e+08 | I10: =IFERROR(C10-H10,0) -> -1.8486762e+08 | J10: =IFERROR((C10-H10)/ABS(H10),0) -> -0.94002243 | K10: {=_xll.DBR($A$5,B10,$D$1,$L$6,$L$5,"Karşlılık Sonrası - Aylık")} -> 1.4725988e+08 | L10: =IFERROR((C10-K10)/ABS(K10),0) -> -0.91990101 | N10: {=_xll.DBR($A$5,B10,$D$1,$O$6,$O$5,"Karşılık Sonrası - YTD")} -> 2.1649812e+09 | P10: {=_xll.DBR($A$6,B10,$D$1,"Departman Toplam",$R$6,$R$5&"-YTD","Amount Cost")} -> 2.3876338e+09 | Q10: =IFERROR(N10-P10,0) -> -2.2265266e+08 | R10: =IFERROR((N10-P10)/ABS(P10),0) -> -0.093252432 | S10: {=_xll.DBR($A$6,B10,$D$1,"Departman Toplam",$U$6,$U$5&"-YTD","Amount Cost")} -> 2.3130904e+09 | T10: =IFERROR(N10-S10,0) -> -1.481092e+08 | U10: =IFERROR((N10-S10)/ABS(S10),0) -> -0.064030875 | V10: {=_xll.DBR($A$5,B10,$D$1,$W$6,$W$5,"Karşılık Sonrası - YTD")} -> 1.3751742e+09 | W10: =IFERROR((N10-V10)/ABS(V10),0) -> 0.5743323
B11: Salary | C11: {=_xll.DBR($A$5,B11,$D$1,$D$6,$D$5,"Karşlılık Sonrası - Aylık")} -> 7686437 | E11: {=_xll.DBR($A$6,B11,$D$1,"Departman Toplam",$G$6,$G$5,"Amount Cost")} -> 1.0572501e+08 | F11: =IFERROR(C11-E11,0) -> -98038573 | G11: =IFERROR((C11-E11)/ABS(E11),0) -> -0.92729784 | H11: {=_xll.DBR($A$6,B11,$D$1,"Departman Toplam",$J$6,$J$5,"Amount Cost")} -> 74048275 | I11: =IFERROR(C11-H11,0) -> -66361838 | J11: =IFERROR((C11-H11)/ABS(H11),0) -> -0.89619695 | K11: {=_xll.DBR($A$5,B11,$D$1,$L$6,$L$5,"Karşlılık Sonrası - Aylık")} -> 70772503 | L11: =IFERROR((C11-K11)/ABS(K11),0) -> -0.89139233 | N11: {=_xll.DBR($A$5,B11,$D$1,$O$6,$O$5,"Karşılık Sonrası - YTD")} -> 9.3203447e+08 | P11: {=_xll.DBR($A$6,B11,$D$1,"Departman Toplam",$R$6,$R$5&"-YTD","Amount Cost")} -> 1.1062148e+09 | Q11: =IFERROR(N11-P11,0) -> -1.7418035e+08 | R11: =IFERROR((N11-P11)/ABS(P11),0) -> -0.15745617 | S11: {=_xll.DBR($A$6,B11,$D$1,"Departman Toplam",$U$6,$U$5&"-YTD","Amount Cost")} -> 9.8307197e+08 | T11: =IFERROR(N11-S11,0) -> -51037496 | U11: =IFERROR((N11-S11)/ABS(S11),0) -> -0.051916338 | V11: {=_xll.DBR($A$5,B11,$D$1,$W$6,$W$5,"Karşılık Sonrası - YTD")} -> 6.4038561e+08 | W11: =IFERROR((N11-V11)/ABS(V11),0) -> 0.45542695
A12: tm1:Period | B12: Salary (1/3) | C12: {=_xll.DBR($A$5,B12,$D$1,$D$6,$D$5,"Karşlılık Sonrası - Aylık")} -> 2925496.2 | E12: {=_xll.DBR($A$6,B12,$D$1,"Departman Toplam",$G$6,$G$5,"Amount Cost")} -> 37691766 | F12: =IFERROR(C12-E12,0) -> -34766270 | G12: =IFERROR((C12-E12)/ABS(E12),0) -> -0.92238368 | H12: {=_xll.DBR($A$6,B12,$D$1,"Departman Toplam",$J$6,$J$5,"Amount Cost")} -> 26892111 | I12: =IFERROR(C12-H12,0) -> -23966615 | J12: =IFERROR((C12-H12)/ABS(H12),0) -> -0.89121359 | K12: {=_xll.DBR($A$5,B12,$D$1,$L$6,$L$5,"Karşlılık Sonrası - Aylık")} -> 23000927 | L12: =IFERROR((C12-K12)/ABS(K12),0) -> -0.87280964 | N12: {=_xll.DBR($A$5,B12,$D$1,$O$6,$O$5,"Karşılık Sonrası - YTD")} -> 2.9931177e+08 | P12: {=_xll.DBR($A$6,B12,$D$1,"Departman Toplam",$R$6,$R$5&"-YTD","Amount Cost")} -> 3.7947606e+08 | Q12: =IFERROR(N12-P12,0) -> -80164290 | R12: =IFERROR((N12-P12)/ABS(P12),0) -> -0.21124993 | S12: {=_xll.DBR($A$6,B12,$D$1,"Departman Toplam",$U$6,$U$5&"-YTD","Amount Cost")} -> 3.2375755e+08 | T12: =IFERROR(N12-S12,0) -> -24445784 | U12: =IFERROR((N12-S12)/ABS(S12),0) -> -0.075506451 | V12: {=_xll.DBR($A$5,B12,$D$1,$W$6,$W$5,"Karşılık Sonrası - YTD")} -> 2.1306438e+08 | W12: =IFERROR((N12-V12)/ABS(V12),0) -> 0.40479499
B13: Vacation Fees | C13: {=_xll.DBR($A$5,B13,$D$1,$D$6,$D$5,"Karşlılık Sonrası - Aylık")} -> 0 | E13: {=_xll.DBR($A$6,B13,$D$1,"Departman Toplam",$G$6,$G$5,"Amount Cost")} -> 559794 | F13: =IFERROR(C13-E13,0) -> -559794 | G13: =IFERROR((C13-E13)/ABS(E13),0) -> -1 | H13: {=_xll.DBR($A$6,B13,$D$1,"Departman Toplam",$J$6,$J$5,"Amount Cost")} -> 492428.1 | I13: =IFERROR(C13-H13,0) -> -492428.1 | J13: =IFERROR((C13-H13)/ABS(H13),0) -> -1 | K13: {=_xll.DBR($A$5,B13,$D$1,$L$6,$L$5,"Karşlılık Sonrası - Aylık")} -> 177162.23 | L13: =IFERROR((C13-K13)/ABS(K13),0) -> -1 | N13: {=_xll.DBR($A$5,B13,$D$1,$O$6,$O$5,"Karşılık Sonrası - YTD")} -> 11886708 | P13: {=_xll.DBR($A$6,B13,$D$1,"Departman Toplam",$R$6,$R$5&"-YTD","Amount Cost")} -> 8572670 | Q13: =IFERROR(N13-P13,0) -> 3314037.6 | R13: =IFERROR((N13-P13)/ABS(P13),0) -> 0.38658173 | S13: {=_xll.DBR($A$6,B13,$D$1,"Departman Toplam",$U$6,$U$5&"-YTD","Amount Cost")} -> 10660509 | T13: =IFERROR(N13-S13,0) -> 1226198.9 | U13: =IFERROR((N13-S13)/ABS(S13),0) -> 0.11502256 | V13: {=_xll.DBR($A$5,B13,$D$1,$W$6,$W$5,"Karşılık Sonrası - YTD")} -> 4503944.6 | W13: =IFERROR((N13-V13)/ABS(V13),0) -> 1.6391772
B14: Holiday Fees | C14: {=_xll.DBR($A$5,B14,$D$1,$D$6,$D$5,"Karşlılık Sonrası - Aylık")} -> 0 | E14: {=_xll.DBR($A$6,B14,$D$1,"Departman Toplam",$G$6,$G$5,"Amount Cost")} -> 0 | F14: =IFERROR(C14-E14,0) -> 0 | G14: =IFERROR((C14-E14)/ABS(E14),0) -> 0 | H14: {=_xll.DBR($A$6,B14,$D$1,"Departman Toplam",$J$6,$J$5,"Amount Cost")} -> 0 | I14: =IFERROR(C14-H14,0) -> 0 | J14: =IFERROR((C14-H14)/ABS(H14),0) -> 0 | K14: {=_xll.DBR($A$5,B14,$D$1,$L$6,$L$5,"Karşlılık Sonrası - Aylık")} -> 0 | L14: =IFERROR((C14-K14)/ABS(K14),0) -> 0 | N14: {=_xll.DBR($A$5,B14,$D$1,$O$6,$O$5,"Karşılık Sonrası - YTD")} -> 7755557.1 | P14: {=_xll.DBR($A$6,B14,$D$1,"Departman Toplam",$R$6,$R$5&"-YTD","Amount Cost")} -> 6602850 | Q14: =IFERROR(N14-P14,0) -> 1152707.1 | R14: =IFERROR((N14-P14)/ABS(P14),0) -> 0.1745772 | S14: {=_xll.DBR($A$6,B14,$D$1,"Departman Toplam",$U$6,$U$5&"-YTD","Amount Cost")} -> 7755557.1 | T14: =IFERROR(N14-S14,0) -> 0 | U14: =IFERROR((N14-S14)/ABS(S14),0) -> 0 | V14: {=_xll.DBR($A$5,B14,$D$1,$W$6,$W$5,"Karşılık Sonrası - YTD")} -> 4364415 | W14: =IFERROR((N14-V14)/ABS(V14),0) -> 0.77699807
B15: Heating Aids | C15: {=_xll.DBR($A$5,B15,$D$1,$D$6,$D$5,"Karşlılık Sonrası - Aylık")} -> 0 | E15: {=_xll.DBR($A$6,B15,$D$1,"Departman Toplam",$G$6,$G$5,"Amount Cost")} -> 1065300 | F15: =IFERROR(C15-E15,0) -> -1065300 | G15: =IFERROR((C15-E15)/ABS(E15),0) -> -1 | H15: {=_xll.DBR($A$6,B15,$D$1,"Departman Toplam",$J$6,$J$5,"Amount Cost")} -> 749420 | I15: =IFERROR(C15-H15,0) -> -749420 | J15: =IFERROR((C15-H15)/ABS(H15),0) -> -1 | K15: {=_xll.DBR($A$5,B15,$D$1,$L$6,$L$5,"Karşlılık Sonrası - Aylık")} -> 1571427.2 | L15: =IFERROR((C15-K15)/ABS(K15),0) -> -1 | N15: {=_xll.DBR($A$5,B15,$D$1,$O$6,$O$5,"Karşılık Sonrası - YTD")} -> 14880498 | P15: {=_xll.DBR($A$6,B15,$D$1,"Departman Toplam",$R$6,$R$5&"-YTD","Amount Cost")} -> 12120040 | Q15: =IFERROR(N15-P15,0) -> 2760458.1 | R15: =IFERROR((N15-P15)/ABS(P15),0) -> 0.22775982 | S15: {=_xll.DBR($A$6,B15,$D$1,"Departman Toplam",$U$6,$U$5&"-YTD","Amount Cost")} -> 15207515 | T15: =IFERROR(N15-S15,0) -> -327016.93 | U15: =IFERROR((N15-S15)/ABS(S15),0) -> -0.02150364 | V15: {=_xll.DBR($A$5,B15,$D$1,$W$6,$W$5,"Karşılık Sonrası - YTD")} -> 16410145 | W15: =IFERROR((N15-V15)/ABS(V15),0) -> -0.093213484
B16: Education Aids | C16: {=_xll.DBR($A$5,B16,$D$1,$D$6,$D$5,"Karşlılık Sonrası - Aylık")} -> 0 | E16: {=_xll.DBR($A$6,B16,$D$1,"Departman Toplam",$G$6,$G$5,"Amount Cost")} -> 0 | F16: =IFERROR(C16-E16,0) -> 0 | G16: =IFERROR((C16-E16)/ABS(E16),0) -> 0 | H16: {=_xll.DBR($A$6,B16,$D$1,"Departman Toplam",$J$6,$J$5,"Amount Cost")} -> 0 | I16: =IFERROR(C16-H16,0) -> 0 | J16: =IFERROR((C16-H16)/ABS(H16),0) -> 0 | K16: {=_xll.DBR($A$5,B16,$D$1,$L$6,$L$5,"Karşlılık Sonrası - Aylık")} -> 3200 | L16: =IFERROR((C16-K16)/ABS(K16),0) -> -1 | N16: {=_xll.DBR($A$5,B16,$D$1,$O$6,$O$5,"Karşılık Sonrası - YTD")} -> 2182763.4 | P16: {=_xll.DBR($A$6,B16,$D$1,"Departman Toplam",$R$6,$R$5&"-YTD","Amount Cost")} -> 1993200 | Q16: =IFERROR(N16-P16,0) -> 189563.35 | R16: =IFERROR((N16-P16)/ABS(P16),0) -> 0.095105032 | S16: {=_xll.DBR($A$6,B16,$D$1,"Departman Toplam",$U$6,$U$5&"-YTD","Amount Cost")} -> 1934550 | T16: =IFERROR(N16-S16,0) -> 248213.35 | U16: =IFERROR((N16-S16)/ABS(S16),0) -> 0.12830547 | V16: {=_xll.DBR($A$5,B16,$D$1,$W$6,$W$5,"Karşılık Sonrası - YTD")} -> 1294816.6 | W16: =IFERROR((N16-V16)/ABS(V16),0) -> 0.68577022
B17: Children Aids | C17: {=_xll.DBR($A$5,B17,$D$1,$D$6,$D$5,"Karşlılık Sonrası - Aylık")} -> 0 | E17: {=_xll.DBR($A$6,B17,$D$1,"Departman Toplam",$G$6,$G$5,"Amount Cost")} -> 182720 | F17: =IFERROR(C17-E17,0) -> -182720 | G17: =IFERROR((C17-E17)/ABS(E17),0) -> -1 | H17: {=_xll.DBR($A$6,B17,$D$1,"Departman Toplam",$J$6,$J$5,"Amount Cost")} -> 173840 | I17: =IFERROR(C17-H17,0) -> -173840 | J17: =IFERROR((C17-H17)/ABS(H17),0) -> -1 | K17: {=_xll.DBR($A$5,B17,$D$1,$L$6,$L$5,"Karşlılık Sonrası - Aylık")} -> 98860.8 | L17: =IFERROR((C17-K17)/ABS(K17),0) -> -1 | N17: {=_xll.DBR($A$5,B17,$D$1,$O$6,$O$5,"Karşılık Sonrası - YTD")} -> 1813497.6 | P17: {=_xll.DBR($A$6,B17,$D$1,"Departman Toplam",$R$6,$R$5&"-YTD","Amount Cost")} -> 2013760 | Q17: =IFERROR(N17-P17,0) -> -200262.4 | R17: =IFERROR((N17-P17)/ABS(P17),0) -> -0.099447005 | S17: {=_xll.DBR($A$6,B17,$D$1,"Departman Toplam",$U$6,$U$5&"-YTD","Amount Cost")} -> 1992617.6 | T17: =IFERROR(N17-S17,0) -> -179120 | U17: =IFERROR((N17-S17)/ABS(S17),0) -> -0.089891809 | V17: {=_xll.DBR($A$5,B17,$D$1,$W$6,$W$5,"Karşılık Sonrası - YTD")} -> 1053623.5 | W17: =IFERROR((N17-V17)/ABS(V17),0) -> 0.72120085
B18: SSK (Social Insurance) | C18: {=_xll.DBR($A$5,B18,$D$1,$D$6,$D$5,"Karşlılık Sonrası - Aylık")} -> 1183220.5 | E18: {=_xll.DBR($A$6,B18,$D$1,"Departman Toplam",$G$6,$G$5,"Amount Cost")} -> 24909883 | F18: =IFERROR(C18-E18,0) -> -23726662 | G18: =IFERROR((C18-E18)/ABS(E18),0) -> -0.95249996 | H18: {=_xll.DBR($A$6,B18,$D$1,"Departman Toplam",$J$6,$J$5,"Amount Cost")} -> 17494816 | I18: =IFERROR(C18-H18,0) -> -16311596 | J18: =IFERROR((C18-H18)/ABS(H18),0) -> -0.93236736 | K18: {=_xll.DBR($A$5,B18,$D$1,$L$6,$L$5,"Karşlılık Sonrası - Aylık")} -> 16740184 | L18: =IFERROR((C18-K18)/ABS(K18),0) -> -0.92931855 | N18: {=_xll.DBR($A$5,B18,$D$1,$O$6,$O$5,"Karşılık Sonrası - YTD")} -> 2.1814835e+08 | P18: {=_xll.DBR($A$6,B18,$D$1,"Departman Toplam",$R$6,$R$5&"-YTD","Amount Cost")} -> 2.5629258e+08 | Q18: =IFERROR(N18-P18,0) -> -38144230 | R18: =IFERROR((N18-P18)/ABS(P18),0) -> -0.1488308 | S18: {=_xll.DBR($A$6,B18,$D$1,"Departman Toplam",$U$6,$U$5&"-YTD","Amount Cost")} -> 2.3182071e+08 | T18: =IFERROR(N18-S18,0) -> -13672358 | U18: =IFERROR((N18-S18)/ABS(S18),0) -> -0.058978155 | V18: {=_xll.DBR($A$5,B18,$D$1,$W$6,$W$5,"Karşılık Sonrası - YTD")} -> 1.38551e+08 | W18: =IFERROR((N18-V18)/ABS(V18),0) -> 0.5744986
B19: Funds (Koç Holding Retirement Fund) | C19: {=_xll.DBR($A$5,B19,$D$1,$D$6,$D$5,"Karşlılık Sonrası - Aylık")} -> 0 | E19: {=_xll.DBR($A$6,B19,$D$1,"Departman Toplam",$G$6,$G$5,"Amount Cost")} -> 6702149.8 | F19: =IFERROR(C19-E19,0) -> -6702149.8 | G19: =IFERROR((C19-E19)/ABS(E19),0) -> -1 | H19: {=_xll.DBR($A$6,B19,$D$1,"Departman Toplam",$J$6,$J$5,"Amount Cost")} -> 4777776.4 | I19: =IFERROR(C19-H19,0) -> -4777776.4 | J19: =IFERROR((C19-H19)/ABS(H19),0) -> -1 | K19: {=_xll.DBR($A$5,B19,$D$1,$L$6,$L$5,"Karşlılık Sonrası - Aylık")} -> 3807835.3 | L19: =IFERROR((C19-K19)/ABS(K19),0) -> -1 | N19: {=_xll.DBR($A$5,B19,$D$1,$O$6,$O$5,"Karşılık Sonrası - YTD")} -> 49984578 | P19: {=_xll.DBR($A$6,B19,$D$1,"Departman Toplam",$R$6,$R$5&"-YTD","Amount Cost")} -> 67482010 | Q19: =IFERROR(N19-P19,0) -> -17497432 | R19: =IFERROR((N19-P19)/ABS(P19),0) -> -0.25929032 | S19: {=_xll.DBR($A$6,B19,$D$1,"Departman Toplam",$U$6,$U$5&"-YTD","Amount Cost")} -> 54621511 | T19: =IFERROR(N19-S19,0) -> -4636932.9 | U19: =IFERROR((N19-S19)/ABS(S19),0) -> -0.084892065 | V19: {=_xll.DBR($A$5,B19,$D$1,$W$6,$W$5,"Karşılık Sonrası - YTD")} -> 34939947 | W19: =IFERROR((N19-V19)/ABS(V19),0) -> 0.43058543
B20: Unemployment Insurance | C20: {=_xll.DBR($A$5,B20,$D$1,$D$6,$D$5,"Karşlılık Sonrası - Aylık")} -> 0 | E20: {=_xll.DBR($A$6,B20,$D$1,"Departman Toplam",$G$6,$G$5,"Amount Cost")} -> 3310283.1 | F20: =IFERROR(C20-E20,0) -> -3310283.1 | G20: =IFERROR((C20-E20)/ABS(E20),0) -> -1 | H20: {=_xll.DBR($A$6,B20,$D$1,"Departman Toplam",$J$6,$J$5,"Amount Cost")} -> 2330992.3 | I20: =IFERROR(C20-H20,0) -> -2330992.3 | J20: =IFERROR((C20-H20)/ABS(H20),0) -> -1 | K20: {=_xll.DBR($A$5,B20,$D$1,$L$6,$L$5,"Karşlılık Sonrası - Aylık")} -> 2221502.3 | L20: =IFERROR((C20-K20)/ABS(K20),0) -> -1 | N20: {=_xll.DBR($A$5,B20,$D$1,$O$6,$O$5,"Karşılık Sonrası - YTD")} -> 28543868 | P20: {=_xll.DBR($A$6,B20,$D$1,"Departman Toplam",$R$6,$R$5&"-YTD","Amount Cost")} -> 34077277 | Q20: =IFERROR(N20-P20,0) -> -5533408.7 | R20: =IFERROR((N20-P20)/ABS(P20),0) -> -0.16237825 | S20: {=_xll.DBR($A$6,B20,$D$1,"Departman Toplam",$U$6,$U$5&"-YTD","Amount Cost")} -> 30454263 | T20: =IFERROR(N20-S20,0) -> -1910394.6 | U20: =IFERROR((N20-S20)/ABS(S20),0) -> -0.062729957 | V20: {=_xll.DBR($A$5,B20,$D$1,$W$6,$W$5,"Karşılık Sonrası - YTD")} -> 19137865 | W20: =IFERROR((N20-V20)/ABS(V20),0) -> 0.49148657
B21: Cash İndemity | C21: {=_xll.DBR($A$5,B21,$D$1,$D$6,$D$5,"Karşlılık Sonrası - Aylık")} -> 0 | E21: {=_xll.DBR($A$6,B21,$D$1,"Departman Toplam",$G$6,$G$5,"Amount Cost")} -> 1078060 | F21: =IFERROR(C21-E21,0) -> -1078060 | G21: =IFERROR((C21-E21)/ABS(E21),0) -> -1 | H21: {=_xll.DBR($A$6,B21,$D$1,"Departman Toplam",$J$6,$J$5,"Amount Cost")} -> 1090380 | I21: =IFERROR(C21-H21,0) -> -1090380 | J21: =IFERROR((C21-H21)/ABS(H21),0) -> -1 | K21: {=_xll.DBR($A$5,B21,$D$1,$L$6,$L$5,"Karşlılık Sonrası - Aylık")} -> 427249.72 | L21: =IFERROR((C21-K21)/ABS(K21),0) -> -1 | N21: {=_xll.DBR($A$5,B21,$D$1,$O$6,$O$5,"Karşılık Sonrası - YTD")} -> 5748108.7 | P21: {=_xll.DBR($A$6,B21,$D$1,"Departman Toplam",$R$6,$R$5&"-YTD","Amount Cost")} -> 11108840 | Q21: =IFERROR(N21-P21,0) -> -5360731.3 | R21: =IFERROR((N21-P21)/ABS(P21),0) -> -0.48256445 | S21: {=_xll.DBR($A$6,B21,$D$1,"Departman Toplam",$U$6,$U$5&"-YTD","Amount Cost")} -> 7454135.8 | T21: =IFERROR(N21-S21,0) -> -1706027.1 | U21: =IFERROR((N21-S21)/ABS(S21),0) -> -0.22886987 | V21: {=_xll.DBR($A$5,B21,$D$1,$W$6,$W$5,"Karşılık Sonrası - YTD")} -> 3768719.7 | W21: =IFERROR((N21-V21)/ABS(V21),0) -> 0.52521524
